<?xml version="1.0" encoding="UTF-8"?>
<testng-results skipped="0" failed="1" ignored="1" total="3" passed="1">
  <reporter-output>
  </reporter-output>
  <suite name="Suite" duration-ms="212" started-at="2019-10-27T10:17:50 IST" finished-at="2019-10-27T10:17:51 IST">
    <groups>
    </groups>
    <test name="Test" duration-ms="212" started-at="2019-10-27T10:17:50 IST" finished-at="2019-10-27T10:17:51 IST">
      <class name="testcases.TestDemoListener">
        <test-method status="FAIL" signature="failedTest()[pri:0, instance:testcases.TestDemoListener@5c5a1b69]" name="failedTest" duration-ms="35" started-at="2019-10-27T10:17:51 IST" finished-at="2019-10-27T10:17:51 IST">
          <exception class="java.lang.AssertionError">
            <message>
              <![CDATA[did not expect to find [false] but found [true]]]>
            </message>
            <full-stacktrace>
              <![CDATA[java.lang.AssertionError: did not expect to find [false] but found [true]
at org.testng.Assert.fail(Assert.java:97)
at org.testng.Assert.failNotEquals(Assert.java:969)
at org.testng.Assert.assertFalse(Assert.java:65)
at org.testng.Assert.assertFalse(Assert.java:75)
at testcases.TestDemoListener.failedTest(TestDemoListener.java:15)
at sun.reflect.NativeMethodAccessorImpl.invoke0(Native Method)
at sun.reflect.NativeMethodAccessorImpl.invoke(Unknown Source)
at sun.reflect.DelegatingMethodAccessorImpl.invoke(Unknown Source)
at java.lang.reflect.Method.invoke(Unknown Source)
at org.testng.internal.MethodInvocationHelper.invokeMethod(MethodInvocationHelper.java:133)
at org.testng.internal.TestInvoker.invokeMethod(TestInvoker.java:584)
at org.testng.internal.TestInvoker.invokeTestMethod(TestInvoker.java:172)
at org.testng.internal.MethodRunner.runInSequence(MethodRunner.java:46)
at org.testng.internal.TestInvoker$MethodInvocationAgent.invoke(TestInvoker.java:804)
at org.testng.internal.TestInvoker.invokeTestMethods(TestInvoker.java:145)
at org.testng.internal.TestMethodWorker.invokeTestMethods(TestMethodWorker.java:146)
at org.testng.internal.TestMethodWorker.run(TestMethodWorker.java:128)
at java.util.ArrayList.forEach(Unknown Source)
at org.testng.TestRunner.privateRun(TestRunner.java:770)
at org.testng.TestRunner.run(TestRunner.java:591)
at org.testng.SuiteRunner.runTest(SuiteRunner.java:402)
at org.testng.SuiteRunner.runSequentially(SuiteRunner.java:396)
at org.testng.SuiteRunner.privateRun(SuiteRunner.java:355)
at org.testng.SuiteRunner.run(SuiteRunner.java:304)
at org.testng.SuiteRunnerWorker.runSuite(SuiteRunnerWorker.java:53)
at org.testng.SuiteRunnerWorker.run(SuiteRunnerWorker.java:96)
at org.testng.TestNG.runSuitesSequentially(TestNG.java:1180)
at org.testng.TestNG.runSuitesLocally(TestNG.java:1102)
at org.testng.TestNG.runSuites(TestNG.java:1032)
at org.testng.TestNG.run(TestNG.java:1000)
at org.testng.remote.AbstractRemoteTestNG.run(AbstractRemoteTestNG.java:115)
at org.testng.remote.RemoteTestNG.initAndRun(RemoteTestNG.java:251)
at org.testng.remote.RemoteTestNG.main(RemoteTestNG.java:77)
]]>
            </full-stacktrace>
          </exception> <!-- java.lang.AssertionError -->
          <reporter-output>
          </reporter-output>
        </test-method> <!-- failedTest -->
        <test-method status="PASS" signature="passTest()[pri:0, instance:testcases.TestDemoListener@5c5a1b69]" name="passTest" duration-ms="3" started-at="2019-10-27T10:17:51 IST" finished-at="2019-10-27T10:17:51 IST">
          <reporter-output>
          </reporter-output>
        </test-method> <!-- passTest -->
      </class> <!-- testcases.TestDemoListener -->
    </test> <!-- Test -->
  </suite> <!-- Suite -->
</testng-results>
